<?xml version="1.0" encoding="utf-8"?>
<!-- =================================================================================== -->
<!-- |    This document was autogenerated by xacro from simple_quadruped.urdf.xacro    | -->
<!-- |    EDITING THIS FILE BY HAND IS NOT RECOMMENDED                                 | -->
<!-- =================================================================================== -->
<robot name="simple_quadruped">
  <!-- MODELS - Utilities -->
  <!--LEG LEFT FRONT -->
  <!--LEG RIGHT FRONT -->
  <!--LEG RIGHT FRONT -->
  <!--LEG RIGHT FRONT -->
  <!-- BASE -->
  <link name="base">
    <visual>
      <origin rpy="0 0 0" xyz="0 0 0"/>
      <geometry>
        <box size="1 0.5 0.1"/>
      </geometry>
      <material name="blue"/>
    </visual>
    <collision>
      <origin rpy="0 0 0" xyz="0 0 0"/>
      <geometry>
        <box size="1 0.5 0.1"/>
      </geometry>
    </collision>
    <inertial>
      <origin rpy="0 0 0" xyz="0 0 0"/>
      <mass value="0.5"/>
      <inertia ixx="0.0421" ixy="0.0" ixz="0.0" iyy="0.0108" iyz="0.0" izz="0.0521"/>
    </inertial>
  </link>
  <joint name="base_to_leg_LF" type="prismatic">
    <origin rpy="0 0 0" xyz="0.475 0.25 0.075"/>
    <axis xyz="0 1 0"/>
    <limit effort="100" lower="-0.1" upper="0.1" velocity="15"/>
    <parent link="base"/>
    <child link="leg_LF_link_1"/>
  </joint>
  <!-- Leg 1 Link 1-->
  <link name="leg_LF_link_1">
    <visual>
      <origin rpy="1.57 0 0" xyz="0 0.06 0"/>
      <geometry>
        <box size="0.05 0.05 0.3"/>
      </geometry>
    </visual>
    <collision>
      <origin rpy="1.57 0 0" xyz="0 0.06 0"/>
      <geometry>
        <box size="0.05 0.05 0.3"/>
      </geometry>
    </collision>
    <inertial>
      <mass value="0.1"/>
      <inertia ixx="0.0008" ixy="0.0" ixz="0.0" iyy="0.0008" iyz="0.0" izz="0.00004"/>
      <origin rpy="1.57 0 0" xyz="0 0.06 0"/>
    </inertial>
  </link>
  <joint name="leg_LF_link_1_to_leg_LF_link_2" type="prismatic">
    <axis xyz="1 0 0"/>
    <origin rpy="0 0 0" xyz="0 0.235 0"/>
    <limit effort="100" lower="-0.1" upper="0.1" velocity="15"/>
    <parent link="leg_LF_link_1"/>
    <child link="leg_LF_link_2"/>
  </joint>
  <!-- Leg 1 Link 2-->
  <link name="leg_LF_link_2">
    <visual>
      <origin rpy="0 1.57 0" xyz="0.125 0 0"/>
      <geometry>
        <box size="0.05 0.05 0.3"/>
      </geometry>
    </visual>
    <collision>
      <origin rpy="0 1.57 0" xyz="0.125 0 0"/>
      <geometry>
        <box size="0.05 0.05 0.3"/>
      </geometry>
    </collision>
    <inertial>
      <mass value="0.1"/>
      <inertia ixx="0.0008" ixy="0.0" ixz="0.0" iyy="0.0008" iyz="0.0" izz="0.00004"/>
      <origin rpy="0 1.57 0" xyz="0.125 0 0"/>
    </inertial>
  </link>
  <joint name="leg_LF_link_2_to_leg_LF_link_3" type="prismatic">
    <axis xyz="0 0 1"/>
    <origin rpy="0 0 0" xyz="0.3 0 0"/>
    <limit effort="100" lower="-0.1" upper="0.1" velocity="15"/>
    <parent link="leg_LF_link_2"/>
    <child link="leg_LF_link_3"/>
  </joint>
  <!-- Leg 1 Link 2-->
  <link name="leg_LF_link_3">
    <visual>
      <origin rpy="0 0 0" xyz="0 0 -0.125"/>
      <geometry>
        <box size="0.05 0.05 0.3"/>
      </geometry>
    </visual>
    <collision>
      <origin rpy="0 0 0" xyz="0 0 -0.125"/>
      <geometry>
        <box size="0.05 0.05 0.3"/>
      </geometry>
    </collision>
    <inertial>
      <mass value="0.1"/>
      <inertia ixx="0.0008" ixy="0.0" ixz="0.0" iyy="0.0008" iyz="0.0" izz="0.00004"/>
      <origin rpy="0 0 0" xyz="0 0 -0.125"/>
    </inertial>
  </link>
  <joint name="leg_LF_link_3_to_foot_LF" type="fixed">
    <origin rpy="0 0 0" xyz="0 0 -0.305"/>
    <parent link="leg_LF_link_3"/>
    <child link="leg_LF_Foot"/>
  </joint>
  <!-- Leg 1 Foot -->
  <link name="leg_LF_Foot">
    <visual>
      <origin rpy="0 0 0" xyz="0 0 0"/>
      <geometry>
        <sphere radius="0.03"/>
      </geometry>
      <material name="blue"/>
    </visual>
    <collision name="leg_LF_foot_collision">
      <origin rpy="0 0 0" xyz="0 0 0"/>
      <geometry>
        <sphere radius="0.025"/>
      </geometry>
    </collision>
    <inertial>
      <mass value="0.1"/>
      <inertia ixx="0.0004" ixy="0.0" ixz="0.0" iyy="0.0004" iyz="0.0" izz="0.0004"/>
      <origin rpy="0 0 0" xyz="0 0 0"/>
    </inertial>
  </link>
  <joint name="base_to_leg_LB" type="prismatic">
    <origin rpy="0 0 0" xyz="-0.475 0.25 0.075"/>
    <axis xyz="0 1 0"/>
    <limit effort="100" lower="-0.1" upper="0.1" velocity="15"/>
    <parent link="base"/>
    <child link="leg_LB_link_1"/>
  </joint>
  <!-- Leg RF Link 1-->
  <link name="leg_LB_link_1">
    <visual>
      <origin rpy="1.57 0 0" xyz="0 0.06 0"/>
      <geometry>
        <box size="0.05 0.05 0.3"/>
      </geometry>
    </visual>
    <collision>
      <origin rpy="1.57 0 0" xyz="0 0.06 0"/>
      <geometry>
        <box size="0.05 0.05 0.3"/>
      </geometry>
    </collision>
    <inertial>
      <mass value="0.1"/>
      <inertia ixx="0.0008" ixy="0.0" ixz="0.0" iyy="0.0008" iyz="0.0" izz="0.00004"/>
      <origin rpy="1.57 0 0" xyz="0 0.06 0"/>
    </inertial>
  </link>
  <joint name="leg_LB_link_1_to_leg_LB_link_2" type="prismatic">
    <axis xyz="1 0 0"/>
    <origin rpy="0 0 0" xyz="0 0.235 0"/>
    <limit effort="100" lower="-0.1" upper="0.1" velocity="15"/>
    <parent link="leg_LB_link_1"/>
    <child link="leg_LB_link_2"/>
  </joint>
  <!-- Leg RF Link 2-->
  <link name="leg_LB_link_2">
    <visual>
      <origin rpy="0 1.57 0" xyz="-0.125 0 0"/>
      <geometry>
        <box size="0.05 0.05 0.3"/>
      </geometry>
    </visual>
    <collision>
      <origin rpy="0 1.57 0" xyz="-0.125 0 0"/>
      <geometry>
        <box size="0.05 0.05 0.3"/>
      </geometry>
    </collision>
    <inertial>
      <mass value="0.1"/>
      <inertia ixx="0.0008" ixy="0.0" ixz="0.0" iyy="0.0008" iyz="0.0" izz="0.00004"/>
      <origin rpy="0 1.57 0" xyz="-0.125 0 0"/>
    </inertial>
  </link>
  <joint name="leg_LB_link_2_to_leg_LB_link_3" type="prismatic">
    <axis xyz="0 0 1"/>
    <origin rpy="0 0 0" xyz="-0.3 0 0"/>
    <limit effort="100" lower="-0.1" upper="0.1" velocity="15"/>
    <parent link="leg_LB_link_2"/>
    <child link="leg_LB_link_3"/>
  </joint>
  <!-- Leg RF Link 3-->
  <link name="leg_LB_link_3">
    <visual>
      <origin rpy="0 0 0" xyz="0 0 -0.125"/>
      <geometry>
        <box size="0.05 0.05 0.3"/>
      </geometry>
    </visual>
    <collision>
      <origin rpy="0 0 0" xyz="0 0 -0.125"/>
      <geometry>
        <box size="0.05 0.05 0.3"/>
      </geometry>
    </collision>
    <inertial>
      <mass value="0.1"/>
      <inertia ixx="0.0008" ixy="0.0" ixz="0.0" iyy="0.0008" iyz="0.0" izz="0.00004"/>
      <origin rpy="0 0 0" xyz="0 0 -0.125"/>
    </inertial>
  </link>
  <joint name="leg_LB_link_3_to_foot_LB" type="fixed">
    <origin rpy="0 0 0" xyz="0 0 -0.305"/>
    <parent link="leg_LB_link_3"/>
    <child link="leg_LB_Foot"/>
  </joint>
  <!-- Leg 1 Foot -->
  <link name="leg_LB_Foot">
    <visual>
      <origin rpy="0 0 0" xyz="0 0 0"/>
      <geometry>
        <sphere radius="0.03"/>
      </geometry>
      <material name="blue"/>
    </visual>
    <collision name="leg_LB_foot_collision">
      <origin rpy="0 0 0" xyz="0 0 0"/>
      <geometry>
        <sphere radius="0.025"/>
      </geometry>
    </collision>
    <inertial>
      <mass value="0.1"/>
      <inertia ixx="0.0004" ixy="0.0" ixz="0.0" iyy="0.0004" iyz="0.0" izz="0.0004"/>
      <origin rpy="0 0 0" xyz="0 0 0"/>
    </inertial>
  </link>
  <joint name="base_to_leg_RF" type="prismatic">
    <origin rpy="0 0 0" xyz="0.475 -0.25 0.075"/>
    <axis xyz="0 1 0"/>
    <limit effort="100" lower="-0.1" upper="0.1" velocity="15"/>
    <parent link="base"/>
    <child link="leg_RF_link_1"/>
  </joint>
  <!-- Leg RF Link 1-->
  <link name="leg_RF_link_1">
    <visual>
      <origin rpy="1.57 0 0" xyz="0 -0.06 0"/>
      <geometry>
        <box size="0.05 0.05 0.3"/>
      </geometry>
    </visual>
    <collision>
      <origin rpy="1.57 0 0" xyz="0 -0.06 0"/>
      <geometry>
        <box size="0.05 0.05 0.3"/>
      </geometry>
    </collision>
    <inertial>
      <mass value="0.1"/>
      <inertia ixx="0.0008" ixy="0.0" ixz="0.0" iyy="0.0008" iyz="0.0" izz="0.00004"/>
      <origin rpy="1.57 0 0" xyz="0 -0.06 0"/>
    </inertial>
  </link>
  <joint name="leg_RF_link_1_to_leg_RF_link_2" type="prismatic">
    <axis xyz="1 0 0"/>
    <origin rpy="0 0 0" xyz="0 -0.235 0"/>
    <limit effort="100" lower="-0.1" upper="0.1" velocity="15"/>
    <parent link="leg_RF_link_1"/>
    <child link="leg_RF_link_2"/>
  </joint>
  <!-- Leg RF Link 2-->
  <link name="leg_RF_link_2">
    <visual>
      <origin rpy="0 1.57 0" xyz="0.125 0 0"/>
      <geometry>
        <box size="0.05 0.05 0.3"/>
      </geometry>
    </visual>
    <collision>
      <origin rpy="0 1.57 0" xyz="0.125 0 0"/>
      <geometry>
        <box size="0.05 0.05 0.3"/>
      </geometry>
    </collision>
    <inertial>
      <mass value="0.1"/>
      <inertia ixx="0.0008" ixy="0.0" ixz="0.0" iyy="0.0008" iyz="0.0" izz="0.00004"/>
      <origin rpy="0 1.57 0" xyz="0.125 0 0"/>
    </inertial>
  </link>
  <joint name="leg_RF_link_2_to_leg_RF_link_3" type="prismatic">
    <axis xyz="0 0 1"/>
    <origin rpy="0 0 0" xyz="0.3 0 0"/>
    <limit effort="100" lower="-0.1" upper="0.1" velocity="15"/>
    <parent link="leg_RF_link_2"/>
    <child link="leg_RF_link_3"/>
  </joint>
  <!-- Leg RF Link 3-->
  <link name="leg_RF_link_3">
    <visual>
      <origin rpy="0 0 0" xyz="0 0 -0.125"/>
      <geometry>
        <box size="0.05 0.05 0.3"/>
      </geometry>
    </visual>
    <collision>
      <origin rpy="0 0 0" xyz="0 0 -0.125"/>
      <geometry>
        <box size="0.05 0.05 0.3"/>
      </geometry>
    </collision>
    <inertial>
      <mass value="0.1"/>
      <inertia ixx="0.0008" ixy="0.0" ixz="0.0" iyy="0.0008" iyz="0.0" izz="0.00004"/>
      <origin rpy="0 0 0" xyz="0 0 -0.125"/>
    </inertial>
  </link>
  <joint name="leg_RF_link_3_to_foot_RF" type="fixed">
    <origin rpy="0 0 0" xyz="0 0 -0.305"/>
    <parent link="leg_RF_link_3"/>
    <child link="leg_RF_Foot"/>
  </joint>
  <!-- Leg 1 Foot -->
  <link name="leg_RF_Foot">
    <visual>
      <origin rpy="0 0 0" xyz="0 0 0"/>
      <geometry>
        <sphere radius="0.03"/>
      </geometry>
      <material name="blue"/>
    </visual>
    <collision name="leg_RF_foot_collision">
      <origin rpy="0 0 0" xyz="0 0 0"/>
      <geometry>
        <sphere radius="0.025"/>
      </geometry>
    </collision>
    <inertial>
      <mass value="0.1"/>
      <inertia ixx="0.0004" ixy="0.0" ixz="0.0" iyy="0.0004" iyz="0.0" izz="0.0004"/>
      <origin rpy="0 0 0" xyz="0 0 0"/>
    </inertial>
  </link>
  <joint name="base_to_leg_RB" type="prismatic">
    <origin rpy="0 0 0" xyz="-0.475 -0.25 0.075"/>
    <axis xyz="0 1 0"/>
    <limit effort="100" lower="-0.1" upper="0.1" velocity="15"/>
    <parent link="base"/>
    <child link="leg_RB_link_1"/>
  </joint>
  <!-- Leg RF Link 1-->
  <link name="leg_RB_link_1">
    <visual>
      <origin rpy="1.57 0 0" xyz="0 -0.06 0"/>
      <geometry>
        <box size="0.05 0.05 0.3"/>
      </geometry>
    </visual>
    <collision>
      <origin rpy="1.57 0 0" xyz="0 -0.06 0"/>
      <geometry>
        <box size="0.05 0.05 0.3"/>
      </geometry>
    </collision>
    <inertial>
      <mass value="0.1"/>
      <inertia ixx="0.0008" ixy="0.0" ixz="0.0" iyy="0.0008" iyz="0.0" izz="0.00004"/>
      <origin rpy="1.57 0 0" xyz="0 -0.06 0"/>
    </inertial>
  </link>
  <joint name="leg_RB_link_1_to_leg_RB_link_2" type="prismatic">
    <axis xyz="1 0 0"/>
    <origin rpy="0 0 0" xyz="0 -0.235 0"/>
    <limit effort="100" lower="-0.1" upper="0.1" velocity="15"/>
    <parent link="leg_RB_link_1"/>
    <child link="leg_RB_link_2"/>
  </joint>
  <!-- Leg RF Link 2-->
  <link name="leg_RB_link_2">
    <visual>
      <origin rpy="0 1.57 0" xyz="-0.125 0 0"/>
      <geometry>
        <box size="0.05 0.05 0.3"/>
      </geometry>
    </visual>
    <collision>
      <origin rpy="0 1.57 0" xyz="-0.125 0 0"/>
      <geometry>
        <box size="0.05 0.05 0.3"/>
      </geometry>
    </collision>
    <inertial>
      <mass value="0.1"/>
      <inertia ixx="0.0008" ixy="0.0" ixz="0.0" iyy="0.0008" iyz="0.0" izz="0.00004"/>
      <origin rpy="0 1.57 0" xyz="-0.125 0 0"/>
    </inertial>
  </link>
  <joint name="leg_RB_link_2_to_leg_RB_link_3" type="prismatic">
    <axis xyz="0 0 1"/>
    <origin rpy="0 0 0" xyz="-0.3 0 0"/>
    <limit effort="100" lower="-0.1" upper="0.1" velocity="15"/>
    <parent link="leg_RB_link_2"/>
    <child link="leg_RB_link_3"/>
  </joint>
  <!-- Leg RF Link 3-->
  <link name="leg_RB_link_3">
    <visual>
      <origin rpy="0 0 0" xyz="0 0 -0.125"/>
      <geometry>
        <box size="0.05 0.05 0.3"/>
      </geometry>
    </visual>
    <collision>
      <origin rpy="0 0 0" xyz="0 0 -0.125"/>
      <geometry>
        <box size="0.05 0.05 0.3"/>
      </geometry>
    </collision>
    <inertial>
      <mass value="0.1"/>
      <inertia ixx="0.0008" ixy="0.0" ixz="0.0" iyy="0.0008" iyz="0.0" izz="0.00004"/>
      <origin rpy="0 0 0" xyz="0 0 -0.125"/>
    </inertial>
  </link>
  <joint name="leg_RB_link_3_to_foot_RB" type="fixed">
    <origin rpy="0 0 0" xyz="0 0 -0.305"/>
    <parent link="leg_RB_link_3"/>
    <child link="leg_RB_Foot"/>
  </joint>
  <!-- Leg 1 Foot -->
  <link name="leg_RB_Foot">
    <visual>
      <origin rpy="0 0 0" xyz="0 0 0"/>
      <geometry>
        <sphere radius="0.03"/>
      </geometry>
      <material name="blue"/>
    </visual>
    <collision name="leg_RB_foot_collision">
      <origin rpy="0 0 0" xyz="0 0 0"/>
      <geometry>
        <sphere radius="0.025"/>
      </geometry>
    </collision>
    <inertial>
      <mass value="0.1"/>
      <inertia ixx="0.0004" ixy="0.0" ixz="0.0" iyy="0.0004" iyz="0.0" izz="0.0004"/>
      <origin rpy="0 0 0" xyz="0 0 0"/>
    </inertial>
  </link>
  <!-- Ros control (For future actuated case) -->
  <gazebo>
    <plugin filename="libgazebo_ros_control.so" name="gazebo_ros_control">
      <robotNamespace>simple_quadruped</robotNamespace>
    </plugin>
  </gazebo>
  <!-- Base -->
  <gazebo reference="base">
    <gravity>true</gravity>
    <!-- <selfCollide>true</selfCollide> -->
    <material>Gazebo/Grey</material>
  </gazebo>
  <!-- Leg_LF -->
  <gazebo reference="leg_LF_link_1">
    <gravity>true</gravity>
    <!-- <selfCollide>true</selfCollide> -->
    <material>Gazebo/Grey</material>
  </gazebo>
  <gazebo reference="leg_LF_link_2">
    <gravity>true</gravity>
    <!-- <selfCollide>true</selfCollide> -->
    <material>Gazebo/Grey</material>
  </gazebo>
  <gazebo reference="leg_LF_link_3">
    <gravity>true</gravity>
    <!-- <selfCollide>true</selfCollide> -->
    <material>Gazebo/Grey</material>
  </gazebo>
  <gazebo reference="leg_LF_Foot">
    <gravity>true</gravity>
    <selfCollide>true</selfCollide>
    <material>Gazebo/Grey</material>
    <sensor name="LF_foot_sensor" type="contact">
      <always_on>true</always_on>
      <update_rate>100.0</update_rate>
      <contact>
        <collision>leg_LF_link_3_fixed_joint_lump__leg_LF_foot_collision_collision_1</collision>
        <topic>/foot_contacts/LF_foot_contact</topic>
      </contact>
      <plugin filename="libgazebo_ros_bumper.so" name="LF_foot_bumper">
        <bumperTopicName>/foot_contacts/LF_foot_contact</bumperTopicName>
        <frameName>world</frameName>
      </plugin>
    </sensor>
  </gazebo>
  <!-- Leg_LB -->
  <gazebo reference="leg_LB_link_1">
    <gravity>true</gravity>
    <!-- <selfCollide>true</selfCollide> -->
    <material>Gazebo/Grey</material>
  </gazebo>
  <gazebo reference="leg_LB_link_2">
    <gravity>true</gravity>
    <!-- <selfCollide>true</selfCollide> -->
    <material>Gazebo/Grey</material>
  </gazebo>
  <gazebo reference="leg_LB_link_3">
    <gravity>true</gravity>
    <!-- <selfCollide>true</selfCollide> -->
    <material>Gazebo/Grey</material>
  </gazebo>
  <gazebo reference="leg_LB_Foot">
    <gravity>true</gravity>
    <selfCollide>true</selfCollide>
    <material>Gazebo/Grey</material>
    <sensor name="LB_foot_sensor" type="contact">
      <always_on>true</always_on>
      <update_rate>100.0</update_rate>
      <contact>
        <collision>leg_LB_link_3_fixed_joint_lump__leg_LB_foot_collision_collision_1</collision>
        <topic>/foot_contacts/LB_foot_contact</topic>
      </contact>
      <plugin filename="libgazebo_ros_bumper.so" name="LB_foot_bumper">
        <bumperTopicName>/foot_contacts/LB_foot_contact</bumperTopicName>
        <frameName>world</frameName>
      </plugin>
    </sensor>
  </gazebo>
  <!-- Leg_RF -->
  <gazebo reference="leg_RF_link_1">
    <gravity>true</gravity>
    <!-- <selfCollide>true</selfCollide> -->
    <material>Gazebo/Grey</material>
  </gazebo>
  <gazebo reference="leg_RF_link_2">
    <gravity>true</gravity>
    <!-- <selfCollide>true</selfCollide> -->
    <material>Gazebo/Grey</material>
  </gazebo>
  <gazebo reference="leg_RF_link_3">
    <gravity>true</gravity>
    <!-- <selfCollide>true</selfCollide> -->
    <material>Gazebo/Grey</material>
  </gazebo>
  <gazebo reference="leg_RF_Foot">
    <gravity>true</gravity>
    <selfCollide>true</selfCollide>
    <material>Gazebo/Grey</material>
    <sensor name="RF_foot_sensor" type="contact">
      <always_on>true</always_on>
      <update_rate>100.0</update_rate>
      <contact>
        <collision>leg_RF_link_3_fixed_joint_lump__leg_RF_foot_collision_collision_1</collision>
        <topic>/foot_contacts/RF_foot_contact</topic>
      </contact>
      <plugin filename="libgazebo_ros_bumper.so" name="RF_foot_bumper">
        <bumperTopicName>/foot_contacts/RF_foot_contact</bumperTopicName>
        <frameName>world</frameName>
      </plugin>
    </sensor>
  </gazebo>
  <!-- Leg_RB -->
  <gazebo reference="leg_RB_link_1">
    <gravity>true</gravity>
    <!-- <selfCollide>true</selfCollide> -->
    <material>Gazebo/Grey</material>
  </gazebo>
  <gazebo reference="leg_RB_link_2">
    <gravity>true</gravity>
    <!-- <selfCollide>true</selfCollide> -->
    <material>Gazebo/Grey</material>
  </gazebo>
  <gazebo reference="leg_RB_link_3">
    <gravity>true</gravity>
    <!-- <selfCollide>true</selfCollide> -->
    <material>Gazebo/Grey</material>
  </gazebo>
  <gazebo reference="leg_RB_Foot">
    <gravity>true</gravity>
    <selfCollide>true</selfCollide>
    <material>Gazebo/Grey</material>
    <sensor name="RB_foot_sensor" type="contact">
      <always_on>true</always_on>
      <update_rate>100.0</update_rate>
      <contact>
        <collision>leg_RB_link_3_fixed_joint_lump__leg_RB_foot_collision_collision_1</collision>
        <topic>/foot_contacts/RB_foot_contact</topic>
      </contact>
      <plugin filename="libgazebo_ros_bumper.so" name="RB_foot_bumper">
        <bumperTopicName>/foot_contacts/RB_foot_contact</bumperTopicName>
        <frameName>world</frameName>
      </plugin>
    </sensor>
  </gazebo>
  <!-- LEG LF-->
  <transmission name="base_to_leg_LF_trans">
    <type>transmission_interface/SimpleTransmission</type>
    <joint name="base_to_leg_LF">
      <hardwareInterface>hardware_interface/EffortJointInterface</hardwareInterface>
    </joint>
    <actuator name="base_to_leg_LF_motor">
      <mechanicalReduction>1</mechanicalReduction>
    </actuator>
  </transmission>
  <transmission name="leg_LF_link_1_to_leg_LF_link_2_trans">
    <type>transmission_interface/SimpleTransmission</type>
    <joint name="leg_LF_link_1_to_leg_LF_link_2">
      <hardwareInterface>hardware_interface/EffortJointInterface</hardwareInterface>
    </joint>
    <actuator name="leg_LF_link_1_to_leg_LF_link_2_motor">
      <mechanicalReduction>1</mechanicalReduction>
    </actuator>
  </transmission>
  <transmission name="leg_LF_link_2_to_leg_LF_link_3_trans">
    <type>transmission_interface/SimpleTransmission</type>
    <joint name="leg_LF_link_2_to_leg_LF_link_3">
      <hardwareInterface>hardware_interface/EffortJointInterface</hardwareInterface>
    </joint>
    <actuator name="leg_LF_link_2_to_leg_LF_link_3_motor">
      <mechanicalReduction>1</mechanicalReduction>
    </actuator>
  </transmission>
  <!-- LEG RF-->
  <transmission name="base_to_leg_RF_trans">
    <type>transmission_interface/SimpleTransmission</type>
    <joint name="base_to_leg_RF">
      <hardwareInterface>hardware_interface/EffortJointInterface</hardwareInterface>
    </joint>
    <actuator name="base_to_leg_RF_motor">
      <mechanicalReduction>1</mechanicalReduction>
    </actuator>
  </transmission>
  <transmission name="leg_RF_link_1_to_leg_RF_link_2_trans">
    <type>transmission_interface/SimpleTransmission</type>
    <joint name="leg_RF_link_1_to_leg_RF_link_2">
      <hardwareInterface>hardware_interface/EffortJointInterface</hardwareInterface>
    </joint>
    <actuator name="leg_RF_link_1_to_leg_RF_link_2_motor">
      <mechanicalReduction>1</mechanicalReduction>
    </actuator>
  </transmission>
  <transmission name="leg_RF_link_2_to_leg_RF_link_3_trans">
    <type>transmission_interface/SimpleTransmission</type>
    <joint name="leg_RF_link_2_to_leg_RF_link_3">
      <hardwareInterface>hardware_interface/EffortJointInterface</hardwareInterface>
    </joint>
    <actuator name="leg_RF_link_2_to_leg_RF_link_3_motor">
      <mechanicalReduction>1</mechanicalReduction>
    </actuator>
  </transmission>
  <!-- LEG LB-->
  <transmission name="base_to_leg_LB_trans">
    <type>transmission_interface/SimpleTransmission</type>
    <joint name="base_to_leg_LB">
      <hardwareInterface>hardware_interface/EffortJointInterface</hardwareInterface>
    </joint>
    <actuator name="base_to_leg_LB_motor">
      <mechanicalReduction>1</mechanicalReduction>
    </actuator>
  </transmission>
  <transmission name="leg_LB_link_1_to_leg_LB_link_2_trans">
    <type>transmission_interface/SimpleTransmission</type>
    <joint name="leg_LB_link_1_to_leg_LB_link_2">
      <hardwareInterface>hardware_interface/EffortJointInterface</hardwareInterface>
    </joint>
    <actuator name="leg_LB_link_1_to_leg_LB_link_2_motor">
      <mechanicalReduction>1</mechanicalReduction>
    </actuator>
  </transmission>
  <transmission name="leg_LB_link_2_to_leg_LB_link_3_trans">
    <type>transmission_interface/SimpleTransmission</type>
    <joint name="leg_LB_link_2_to_leg_LB_link_3">
      <hardwareInterface>hardware_interface/EffortJointInterface</hardwareInterface>
    </joint>
    <actuator name="leg_LB_link_2_to_leg_LB_link_3_motor">
      <mechanicalReduction>1</mechanicalReduction>
    </actuator>
  </transmission>
  <!-- LEG RB-->
  <transmission name="base_to_leg_RB_trans">
    <type>transmission_interface/SimpleTransmission</type>
    <joint name="base_to_leg_RB">
      <hardwareInterface>hardware_interface/EffortJointInterface</hardwareInterface>
    </joint>
    <actuator name="base_to_leg_RB_motor">
      <mechanicalReduction>1</mechanicalReduction>
    </actuator>
  </transmission>
  <transmission name="leg_RB_link_1_to_leg_RB_link_2_trans">
    <type>transmission_interface/SimpleTransmission</type>
    <joint name="leg_RB_link_1_to_leg_RB_link_2">
      <hardwareInterface>hardware_interface/EffortJointInterface</hardwareInterface>
    </joint>
    <actuator name="leg_RB_link_1_to_leg_RB_link_2_motor">
      <mechanicalReduction>1</mechanicalReduction>
    </actuator>
  </transmission>
  <transmission name="leg_RB_link_2_to_leg_RB_link_3_trans">
    <type>transmission_interface/SimpleTransmission</type>
    <joint name="leg_RB_link_2_to_leg_RB_link_3">
      <hardwareInterface>hardware_interface/EffortJointInterface</hardwareInterface>
    </joint>
    <actuator name="leg_RB_link_2_to_leg_RB_link_3_motor">
      <mechanicalReduction>1</mechanicalReduction>
    </actuator>
  </transmission>
</robot>

